<?xml version="1.0"?>

<robot xmlns:xacro="http://ros.org/wiki/xacro">

  <!--<xacro:include filename="$(find p2os_urdf)/defs/materials.xacro"/>-->

  <!-- Properties (Constants) -->
  <xacro:property name="M_PI" value="3.14159"/>
  <!-- where to find all meshes -->
<xacro:property name="mesh_directory" value="package://champ_description/meshes/p3dx_meshes"/>

  <!-- Right/Left Swivel + Hubcap + Wheel -->
  <xacro:macro name="powerbot_swivel_wheel" params="suffix parent reflect">

 <!-- Right/Left Swivel support-->

	<link name="${suffix}_swivel_support">
		<inertial>
			<mass value="0.1"/>	
			<origin xyz="0 0 0" rpy="0 0 0"/>
			<inertia ixx="0.01" ixy="0" ixz="0"
				 iyy="0.01" iyz="0" izz="0.01"/>
  	 	</inertial>
	<visual name="${suffix}_swivel_support_visual">
		<origin xyz="0 0 0" rpy="0 0 0"/>
		<geometry name="swivel">
			<mesh filename="${mesh_directory}/swivel_support.stl" />
		</geometry>
		<material name="swivel">
			<color rgba="0.9 0.9 0.9 1"/>
		</material>
	</visual>
	<collision>
		<origin xyz="0 0 0" rpy="0 0 0"/>
		<geometry>
			<mesh filename="${mesh_directory}/swivel_support.stl" scale= "1.005 1.005 1.005"/>
		</geometry>
	</collision>
	</link>
	<gazebo reference="swivel">
		<material value="Gazebo/Grey"/>
	</gazebo>

	
	<joint name="${suffix}_base_swivel_support_joint" type="fixed">
		<origin xyz="-0.215 ${reflect*0.2} -0.0915" rpy="0 0 0"/>
		<parent link="${parent}"/>
		<child link="${suffix}_swivel_support"/>
	</joint>


	<joint name="${suffix}_base_swivel_joint" type="continuous">
		<origin xyz="0 0 -0.04855" rpy="0 0 0"/>
		<axis xyz="0 0 1"/>
	    <limit effort="100" velocity="100" k_velocity="0" />
	    <joint_properties damping="0.0" friction="0.0" />
		<parent link="${suffix}_swivel_support"/>
		<child link="powerbot_${suffix}_swivel"/>
	</joint>

    <link name="powerbot_${suffix}_swivel">
		<inertial>
			<mass value="2.0"/>	
			<origin xyz="0 0 0" rpy="0 0 0"/>
			<inertia ixx="0.001" ixy="0" ixz="0"
				 iyy="0.001" iyz="0" izz="0.001"/>
  	 	</inertial>
	<visual name="powerbot_${suffix}_swivel_visual">
		<origin xyz="0 0 0" rpy="0 0 0"/>
		<geometry name="swivel">
			<mesh filename="${mesh_directory}/swivel.stl" />
		</geometry>
		<material name="swivel">
			<color rgba="0.5 0.5 0.5 1"/>
		</material>
	</visual>
	<collision>
		<origin xyz="0 0 0" rpy="0 0 0"/>
		<geometry>
			<mesh filename="${mesh_directory}/swivel.stl" scale= "1.005 1.005 1.005"/>
		</geometry>
	</collision>
	</link>
	<gazebo reference="swivel">
		<material value="Gazebo/Grey"/>
	</gazebo>


 <!-- Center Wheel + Hubcap -->

    <link name="powerbot_${suffix}_swivel_hubcap">
	<inertial>
			<mass value="0.01"/>	
			<origin xyz="0 0 0"/>
			<inertia ixx="0.00012411765597" ixy="0.0" ixz="0.0"
				 iyy="0.00015218160428" iyz="0.0" izz="0.00011763977943"/>
   	</inertial>
	<visual name="powerbot_${suffix}_swivel_hubcap">
		<origin xyz="0 0 0" rpy="0 0 0"/>
		<geometry name="pioneer_geom">
			<mesh filename="${mesh_directory}/center_hubcap.stl" />
		</geometry>
		<material name="swivel">
			<color rgba="0.5 0.5 0.5 1"/>
		</material>
	</visual>
	<collision>
		<origin xyz="0 0 0" rpy="0 0 0"/>
		<geometry>
			<mesh filename="${mesh_directory}/center_hubcap.stl" />
		</geometry>
	</collision>
</link>

  <gazebo reference="powerbot_${suffix}_swivel_hubcap">
	<material value="Gazebo/Black"/>
  </gazebo>



    <joint name="${suffix}_swivel_wheel_joint" type="continuous">
      <axis xyz="0 1 0"/>
      <anchor xyz="0 0 0"/>
      <limit effort="100" velocity="100" />
      <joint_properties damping="0.0" friction="0.0" />
      <origin xyz="-0.036 0 -0.029" rpy="0 0 0"/>
      <parent link="powerbot_${suffix}_swivel"/>
      <child link="powerbot_${suffix}_swivel_wheel"/>
    </joint>


<link name="powerbot_${suffix}_swivel_wheel">
	<inertial>
			<mass value="2.0"/>	
			<origin xyz="0 0 0"/>
			<inertia ixx="0.00012411765597" ixy="0.0" ixz="0.0"
				 iyy="0.00015218160428" iyz="0.0" izz="0.00011763977943"/>
  	 	</inertial>
	<visual name="powerbot_${suffix}_swivel_wheel">
		<origin xyz="0 0 0" rpy="0 0 0"/>
		<geometry name="powerbot_${suffix}_swivel_wheel">
			<mesh filename="${mesh_directory}/center_wheel.stl" />
		</geometry>
		<material name="WheelBlack">
			<color rgba="0.117 0.117 0.117 1"/>
		</material>
	</visual>
	<collision>
		<origin xyz="0 0 0" rpy=" ${-3.1415927/2} 0 0"/>
		<geometry>
			<cylinder radius="0.052" length="0.0422"/>
		</geometry>
	</collision>
  </link>

  <joint name="powerbot_${suffix}_swivel_hubcap_joint" type="fixed">
	<origin xyz="0 0 0" rpy="0 0 0"/>
	<parent link="powerbot_${suffix}_swivel_wheel"/>
	<child link="powerbot_${suffix}_swivel_hubcap"/>
  </joint>


    <gazebo reference="powerbot_${suffix}_swivel_wheel">
      <material value="Gazebo/Grey"/>
      <mu1>0.5</mu1>
      <mu2>50.0</mu2>
      <kp>100000000.0</kp>
      <kd>1.0</kd>
    </gazebo>

  </xacro:macro>


</robot>

