<?xml version="1.0" ?>
<!-- =================================================================================== -->
<!-- |    This document was autogenerated by xacro from powerbot.xacro                 | -->
<!-- |    EDITING THIS FILE BY HAND IS NOT RECOMMENDED                                 | -->
<!-- =================================================================================== -->
<robot name="powerbot" xmlns:controller="http://playerstage.sourceforge.net/gazebo/xmlschema/#controller" xmlns:interface="http://playerstage.sourceforge.net/gazebo/xmlschema/#interface" xmlns:sensor="http://playerstage.sourceforge.net/gazebo/xmlschema/#sensor">
  <!--<xacro:include filename="$(find p2os_urdf)/defs/materials.xacro"/>-->
  <!--<xacro:include filename="$(find p2os_urdf)/defs/materials.xacro"/>-->
  <!--<xacro:include filename="$(find p2os_urdf)/defs/materials.xacro"/>-->
  <!-- 0.148 -->
  <!-- Right/${suffix} Swivel support

	<link name="${suffix}_swivel_support">
		<inertial>
			<mass value="0.1"/>	
			<origin xyz="0 0 0" rpy="0 0 0"/>
			<inertia ixx="0.01" ixy="0" ixz="0"
				 iyy="0.01" iyz="0" izz="0.01"/>
  	 	</inertial>
	<visual name="${suffix}_swivel_support_visual">
		<origin xyz="0 0 0" rpy="0 0 0"/>
		<geometry name="swivel">
			<mesh filename="${mesh_directory}/swivel_support.stl" />
		</geometry>
		<material name="swivel">
			<color rgba="0.9 0.9 0.9 1"/>
		</material>
	</visual>
	<collision>
		<origin xyz="0 0 0" rpy="0 0 0"/>
		<geometry>
			<mesh filename="${mesh_directory}/swivel_support.stl" scale= "1.005 1.005 1.005"/>
		</geometry>
	</collision>
	</link>
	<gazebo reference="swivel">
		<material value="Gazebo/Grey"/>
	</gazebo>

	<joint name="${suffix}_base_swivel_joint" type="continuous">
		<origin xyz="0 0 -0.04855" rpy="0 0 0"/>
		<axis xyz="0 0 1"/>
	    <limit effort="100" velocity="100" k_velocity="0" />
	    <joint_properties damping="0.0" friction="0.0" />
		<parent link="${suffix}_swivel_support"/>
		<child link="powerbot_${suffix}_swivel"/>
	</joint>
-->
  <joint name="left_base_swivel_support_joint" type="fixed">
    <origin rpy="0 0 0" xyz="-0.215 0.2 -0.145"/>
    <parent link="base_center"/>
    <child link="powerbot_left_swivel_support"/>
  </joint>
  <!-- Support bowl-->
  <link name="powerbot_left_swivel_support">
    <inertial>
      <mass value="2.0"/>
      <origin rpy="0 0 0" xyz="0 0 0"/>
      <inertia ixx="0.001" ixy="0" ixz="0" iyy="0.001" iyz="0" izz="0.001"/>
    </inertial>
    <visual>
      <origin rpy="0 0 0" xyz="0 0 0"/>
      <geometry name="swivel">
        <mesh filename="package://technical_project/meshes/p3dx_meshes/bowl.stl"/>
      </geometry>
    </visual>
    <collision>
      <origin rpy="0 0 0" xyz="0 0 0"/>
      <geometry>
        <mesh filename="package://technical_project/meshes/p3dx_meshes/bowl.stl" scale="1.005 1.005 1.005"/>
      </geometry>
    </collision>
  </link>
  <gazebo reference="powerbot_left_swivel_support">
    <material value="Gazebo/Yellow"/>
  </gazebo>
  <!-- ${suffix} support swivel ball joint -->
  <joint name="left_ballRoot_joint" type="fixed">
    <origin xyz="0 0 0"/>
    <parent link="powerbot_left_swivel_support"/>
    <child link="left_ball"/>
  </joint>
  <link name="left_ball">
    <inertial>
      <mass value="2.0"/>
      <origin xyz="0 0 0"/>
      <inertia ixx="0.00288" ixy="0.0" ixz="0.0" iyy="0.00288" iyz="0.0" izz="0.00288"/>
    </inertial>
  </link>
  <joint name="left_ballPsi_joint" type="continuous">
    <origin rpy="0 0 0" xyz="0 0 0"/>
    <parent link="left_ball"/>
    <child link="left_ball_psi_link"/>
    <axis xyz="0 0 1"/>
    <dynamics damping="0.09"/>
  </joint>
  <link name="left_ball_psi_link">
    <inertial>
      <mass value="2.0"/>
      <origin xyz="0 0 0"/>
      <inertia ixx="0.00288" ixy="0.0" ixz="0.0" iyy="0.00288" iyz="0.0" izz="0.00288"/>
    </inertial>
  </link>
  <joint name="left_ballTheta_joint" type="continuous">
    <origin rpy="0 0 0" xyz="0 0 0"/>
    <parent link="left_ball_psi_link"/>
    <child link="left_ball_theta_link"/>
    <axis xyz="0 1 0"/>
    <dynamics damping="0.09"/>
  </joint>
  <link name="left_ball_theta_link">
    <inertial>
      <mass value="2.0"/>
      <origin xyz="0 0 0"/>
      <inertia ixx="0.00288" ixy="0.0" ixz="0.0" iyy="0.00288" iyz="0.0" izz="0.00288"/>
    </inertial>
  </link>
  <joint name="left_ballPhi_joint" type="continuous">
    <origin rpy="0 0 0" xyz="0 0 0"/>
    <parent link="left_ball_theta_link"/>
    <child link="powerbot_left_swivel_ball"/>
    <axis xyz="1 0 0"/>
    <dynamics damping="0.09"/>
  </joint>
  <!--
-->
  <!-- Swivel ball -->
  <link name="powerbot_left_swivel_ball">
    <inertial>
      <mass value="2.0"/>
      <origin xyz="0 0 0"/>
      <inertia ixx="0.00288" ixy="0.0" ixz="0.0" iyy="0.00288" iyz="0.0" izz="0.00288"/>
    </inertial>
    <visual>
      <origin rpy="0 0 0" xyz="0 0 0"/>
      <geometry name="powerbot_left_swivel_ball">
        <mesh filename="package://technical_project/meshes/p3dx_meshes/ball.stl"/>
      </geometry>
      <material name="Wheeleft_black">
        <color rgba="0.117 0.117 0.117 1"/>
      </material>
    </visual>
    <collision>
      <origin rpy=" -1.57079635 0 0" xyz="0 0 0"/>
      <geometry>
        <sphere radius="0.06"/>
      </geometry>
    </collision>
  </link>
  <gazebo reference="powerbot_left_swivel_ball">
    <material value="Gazebo/Black"/>
    <mu1>100</mu1>
    <mu2>200</mu2>
    <kp>100000000.0</kp>
    <kd>1.0</kd>
  </gazebo>
  <!-- Right/${suffix} Swivel support

	<link name="${suffix}_swivel_support">
		<inertial>
			<mass value="0.1"/>	
			<origin xyz="0 0 0" rpy="0 0 0"/>
			<inertia ixx="0.01" ixy="0" ixz="0"
				 iyy="0.01" iyz="0" izz="0.01"/>
  	 	</inertial>
	<visual name="${suffix}_swivel_support_visual">
		<origin xyz="0 0 0" rpy="0 0 0"/>
		<geometry name="swivel">
			<mesh filename="${mesh_directory}/swivel_support.stl" />
		</geometry>
		<material name="swivel">
			<color rgba="0.9 0.9 0.9 1"/>
		</material>
	</visual>
	<collision>
		<origin xyz="0 0 0" rpy="0 0 0"/>
		<geometry>
			<mesh filename="${mesh_directory}/swivel_support.stl" scale= "1.005 1.005 1.005"/>
		</geometry>
	</collision>
	</link>
	<gazebo reference="swivel">
		<material value="Gazebo/Grey"/>
	</gazebo>

	<joint name="${suffix}_base_swivel_joint" type="continuous">
		<origin xyz="0 0 -0.04855" rpy="0 0 0"/>
		<axis xyz="0 0 1"/>
	    <limit effort="100" velocity="100" k_velocity="0" />
	    <joint_properties damping="0.0" friction="0.0" />
		<parent link="${suffix}_swivel_support"/>
		<child link="powerbot_${suffix}_swivel"/>
	</joint>
-->
  <joint name="right_base_swivel_support_joint" type="fixed">
    <origin rpy="0 0 0" xyz="-0.215 -0.2 -0.145"/>
    <parent link="base_center"/>
    <child link="powerbot_right_swivel_support"/>
  </joint>
  <!-- Support bowl-->
  <link name="powerbot_right_swivel_support">
    <inertial>
      <mass value="2.0"/>
      <origin rpy="0 0 0" xyz="0 0 0"/>
      <inertia ixx="0.001" ixy="0" ixz="0" iyy="0.001" iyz="0" izz="0.001"/>
    </inertial>
    <visual>
      <origin rpy="0 0 0" xyz="0 0 0"/>
      <geometry name="swivel">
        <mesh filename="package://technical_project/meshes/p3dx_meshes/bowl.stl"/>
      </geometry>
    </visual>
    <collision>
      <origin rpy="0 0 0" xyz="0 0 0"/>
      <geometry>
        <mesh filename="package://technical_project/meshes/p3dx_meshes/bowl.stl" scale="1.005 1.005 1.005"/>
      </geometry>
    </collision>
  </link>
  <gazebo reference="powerbot_right_swivel_support">
    <material value="Gazebo/Yellow"/>
  </gazebo>
  <!-- ${suffix} support swivel ball joint -->
  <joint name="right_ballRoot_joint" type="fixed">
    <origin xyz="0 0 0"/>
    <parent link="powerbot_right_swivel_support"/>
    <child link="right_ball"/>
  </joint>
  <link name="right_ball">
    <inertial>
      <mass value="2.0"/>
      <origin xyz="0 0 0"/>
      <inertia ixx="0.00288" ixy="0.0" ixz="0.0" iyy="0.00288" iyz="0.0" izz="0.00288"/>
    </inertial>
  </link>
  <joint name="right_ballPsi_joint" type="continuous">
    <origin rpy="0 0 0" xyz="0 0 0"/>
    <parent link="right_ball"/>
    <child link="right_ball_psi_link"/>
    <axis xyz="0 0 1"/>
    <dynamics damping="0.09"/>
  </joint>
  <link name="right_ball_psi_link">
    <inertial>
      <mass value="2.0"/>
      <origin xyz="0 0 0"/>
      <inertia ixx="0.00288" ixy="0.0" ixz="0.0" iyy="0.00288" iyz="0.0" izz="0.00288"/>
    </inertial>
  </link>
  <joint name="right_ballTheta_joint" type="continuous">
    <origin rpy="0 0 0" xyz="0 0 0"/>
    <parent link="right_ball_psi_link"/>
    <child link="right_ball_theta_link"/>
    <axis xyz="0 1 0"/>
    <dynamics damping="0.09"/>
  </joint>
  <link name="right_ball_theta_link">
    <inertial>
      <mass value="2.0"/>
      <origin xyz="0 0 0"/>
      <inertia ixx="0.00288" ixy="0.0" ixz="0.0" iyy="0.00288" iyz="0.0" izz="0.00288"/>
    </inertial>
  </link>
  <joint name="right_ballPhi_joint" type="continuous">
    <origin rpy="0 0 0" xyz="0 0 0"/>
    <parent link="right_ball_theta_link"/>
    <child link="powerbot_right_swivel_ball"/>
    <axis xyz="1 0 0"/>
    <dynamics damping="0.09"/>
  </joint>
  <!--
-->
  <!-- Swivel ball -->
  <link name="powerbot_right_swivel_ball">
    <inertial>
      <mass value="2.0"/>
      <origin xyz="0 0 0"/>
      <inertia ixx="0.00288" ixy="0.0" ixz="0.0" iyy="0.00288" iyz="0.0" izz="0.00288"/>
    </inertial>
    <visual>
      <origin rpy="0 0 0" xyz="0 0 0"/>
      <geometry name="powerbot_right_swivel_ball">
        <mesh filename="package://technical_project/meshes/p3dx_meshes/ball.stl"/>
      </geometry>
      <material name="Wheeright_black">
        <color rgba="0.117 0.117 0.117 1"/>
      </material>
    </visual>
    <collision>
      <origin rpy=" -1.57079635 0 0" xyz="0 0 0"/>
      <geometry>
        <sphere radius="0.06"/>
      </geometry>
    </collision>
  </link>
  <gazebo reference="powerbot_right_swivel_ball">
    <material value="Gazebo/Black"/>
    <mu1>100</mu1>
    <mu2>200</mu2>
    <kp>100000000.0</kp>
    <kd>1.0</kd>
  </gazebo>
  <link name="powerbot_left_wheel">
    <inertial>
      <mass value="5.25"/>
      <origin xyz="0 0 0"/>
      <inertia ixx="0.012411765597" ixy="0" ixz="0" iyy="0.015218160428" iyz="0" izz="0.011763977943"/>
    </inertial>
    <visual>
      <origin rpy="0 0 0" xyz="0 0 0"/>
      <geometry>
        <mesh filename="package://technical_project/meshes/p3dx_meshes/wheel.stl"/>
      </geometry>
      <material name="WheelBlack">
        <color rgba="0.117 0.117 0.117 1"/>
      </material>
    </visual>
    <collision>
      <origin rpy="-1.57079635 0 0" xyz="0 0 0"/>
      <geometry>
        <cylinder length="0.065" radius="0.133"/>
      </geometry>
      <!--
			<geometry>
				<mesh filename="${mesh_directory}/wheel.stl" scale= "1.005 1.005 1.005"/>
			</geometry>-->
    </collision>
  </link>
  <joint name="base_left_hubcap_joint" type="fixed">
    <origin rpy="0 0 0" xyz="0 0 0"/>
    <parent link="powerbot_left_wheel"/>
    <child link="powerbot_left_hubcap"/>
  </joint>
  <link name="powerbot_left_hubcap">
    <inertial>
      <mass value="0.08"/>
      <origin xyz="0 0 0"/>
      <inertia ixx="0.012411765597" ixy="0" ixz="0" iyy="0.015218160428" iyz="0" izz="0.011763977943"/>
    </inertial>
    <visual>
      <origin rpy="0 0 0" xyz="0 0 0"/>
      <geometry>
        <mesh filename="package://technical_project/meshes/p3dx_meshes/hubcap.stl"/>
      </geometry>
      <material name="HubcapYellow">
        <color rgba="1.0 0.811 0.151 1.0"/>
      </material>
    </visual>
  </link>
  <!-- The transmission tag is used only by ros_control -->
  <!--<transmission type="pr2_mechanism_model/SimpleTransmission" name="${parent}_${suffix}_wheel_trans">
        <actuator name="base_${suffix}_wheel_motor" />
        <joint name="base_${suffix}_wheel_joint" />
        <hardwareInterface>hardware_interface/VelocityJointInterface</hardwareInterface>
        <mechanicalReduction>${reflect * 624/35 * 80/19}</mechanicalReduction>
        </transmission>-->
  <joint name="base_left_wheel_joint" type="continuous">
    <axis xyz="0 1 0"/>
    <anchor xyz="0 0 0"/>
    <limit effort="100" velocity="100"/>
    <joint_properties damping="0.0" friction="0.0"/>
    <origin rpy="0 0 0" xyz="0.084 0.35 -0.07"/>
    <parent link="base_center"/>
    <child link="powerbot_left_wheel"/>
  </joint>
  <transmission name="left_wheel_trans">
    <type>transmission_interface/SimpleTransmission</type>
    <joint name="base_left_wheel_joint">
      <hardwareInterface>hardware_interface/VelocityJointInterface</hardwareInterface>
    </joint>
    <actuator name="base_left_wheel_motor">
      <hardwareInterface>hardware_interface/VelocityJointInterface</hardwareInterface>
      <mechanicalReduction>75.06766917293233</mechanicalReduction>
    </actuator>
  </transmission>
  <gazebo reference="powerbot_left_hubcap">
    <material value="Gazebo/Yellow"/>
  </gazebo>
  <gazebo reference="powerbot_left_wheel">
    <material value="Gazebo/Black"/>
    <mu1>0.5</mu1>
    <mu2>50.0</mu2>
    <kp>100000000.0</kp>
    <kd>1.0</kd>
  </gazebo>
  <link name="powerbot_right_wheel">
    <inertial>
      <mass value="5.25"/>
      <origin xyz="0 0 0"/>
      <inertia ixx="0.012411765597" ixy="0" ixz="0" iyy="0.015218160428" iyz="0" izz="0.011763977943"/>
    </inertial>
    <visual>
      <origin rpy="0 0 0" xyz="0 0 0"/>
      <geometry>
        <mesh filename="package://technical_project/meshes/p3dx_meshes/wheel.stl"/>
      </geometry>
      <material name="WheelBlack">
        <color rgba="0.117 0.117 0.117 1"/>
      </material>
    </visual>
    <collision>
      <origin rpy="-1.57079635 0 0" xyz="0 0 0"/>
      <geometry>
        <cylinder length="0.065" radius="0.133"/>
      </geometry>
      <!--
			<geometry>
				<mesh filename="${mesh_directory}/wheel.stl" scale= "1.005 1.005 1.005"/>
			</geometry>-->
    </collision>
  </link>
  <joint name="base_right_hubcap_joint" type="fixed">
    <origin rpy="0 0 0" xyz="0 0 0"/>
    <parent link="powerbot_right_wheel"/>
    <child link="powerbot_right_hubcap"/>
  </joint>
  <link name="powerbot_right_hubcap">
    <inertial>
      <mass value="0.08"/>
      <origin xyz="0 0 0"/>
      <inertia ixx="0.012411765597" ixy="0" ixz="0" iyy="0.015218160428" iyz="0" izz="0.011763977943"/>
    </inertial>
    <visual>
      <origin rpy="0 0 0" xyz="0 0 0"/>
      <geometry>
        <mesh filename="package://technical_project/meshes/p3dx_meshes/hubcap.stl"/>
      </geometry>
      <material name="HubcapYellow">
        <color rgba="1.0 0.811 0.151 1.0"/>
      </material>
    </visual>
  </link>
  <!-- The transmission tag is used only by ros_control -->
  <!--<transmission type="pr2_mechanism_model/SimpleTransmission" name="${parent}_${suffix}_wheel_trans">
        <actuator name="base_${suffix}_wheel_motor" />
        <joint name="base_${suffix}_wheel_joint" />
        <hardwareInterface>hardware_interface/VelocityJointInterface</hardwareInterface>
        <mechanicalReduction>${reflect * 624/35 * 80/19}</mechanicalReduction>
        </transmission>-->
  <joint name="base_right_wheel_joint" type="continuous">
    <axis xyz="0 1 0"/>
    <anchor xyz="0 0 0"/>
    <limit effort="100" velocity="100"/>
    <joint_properties damping="0.0" friction="0.0"/>
    <origin rpy="0 0 0" xyz="0.084 -0.35 -0.07"/>
    <parent link="base_center"/>
    <child link="powerbot_right_wheel"/>
  </joint>
  <transmission name="right_wheel_trans">
    <type>transmission_interface/SimpleTransmission</type>
    <joint name="base_right_wheel_joint">
      <hardwareInterface>hardware_interface/VelocityJointInterface</hardwareInterface>
    </joint>
    <actuator name="base_right_wheel_motor">
      <hardwareInterface>hardware_interface/VelocityJointInterface</hardwareInterface>
      <mechanicalReduction>-75.06766917293233</mechanicalReduction>
    </actuator>
  </transmission>
  <gazebo reference="powerbot_right_hubcap">
    <material value="Gazebo/Yellow"/>
  </gazebo>
  <gazebo reference="powerbot_right_wheel">
    <material value="Gazebo/Black"/>
    <mu1>0.5</mu1>
    <mu2>50.0</mu2>
    <kp>100000000.0</kp>
    <kd>1.0</kd>
  </gazebo>
  <!-- Chassis -->
  <link name="base_center">
    <inertial>
      <mass value="120.0"/>
      <origin xyz="-0.045 0 0.067"/>
      <inertia ixx="1" ixy="0.0" ixz="0.0" iyy="1" iyz="0.0" izz="1"/>
    </inertial>
    <visual>
      <origin rpy="0 0 0" xyz="-0.045 0 0.067"/>
      <geometry name="pioneer_geom">
        <mesh filename="package://technical_project/meshes/p3dx_meshes/chassis.stl"/>
      </geometry>
    </visual>
    <collision>
      <origin rpy="0 0 0" xyz="-0.045 0 0.067"/>
      <geometry>
        <mesh filename="package://technical_project/meshes/p3dx_meshes/chassis.stl" scale="1.01 1.01 1.01"/>
      </geometry>
    </collision>
  </link>
  <gazebo reference="base_center">
    <material value="Gazebo/Yellow"/>
  </gazebo>
  <!-- Top -->
  <joint name="base_top_joint" type="fixed">
    <!--origin xyz="-0.045 0 0.325" rpy="0 0 0"/-->
    <origin rpy="0 0 0" xyz="-0.045 0 0.277"/>
    <parent link="base_center"/>
    <child link="top_plate"/>
  </joint>
  <!-- Top plate -->
  <link name="top_plate">
    <inertial>
      <mass value="0.1"/>
      <origin xyz="0 0 0"/>
      <inertia ixx="1" ixy="0" ixz="0" iyy="1" iyz="0" izz="1"/>
    </inertial>
    <visual>
      <origin rpy="0 0 0" xyz="0 0 0"/>
      <geometry name="top_geom">
        <mesh filename="package://technical_project/meshes/p3dx_meshes/top.stl"/>
      </geometry>
    </visual>
    <collision>
      <origin rpy="0 0 0" xyz="0 0 0"/>
      <geometry>
        <mesh filename="package://technical_project/meshes/p3dx_meshes/top.stl"/>
      </geometry>
    </collision>
  </link>
  <gazebo reference="top_plate">
    <material value="Gazebo/Black"/>
  </gazebo>
  <link name="sensor_link">
    <visual>
      <geometry>
        <box size="0.05 0.1 0.1"/>
      </geometry>
    </visual>
    <inertial>
      <origin rpy="0 0 0" xyz="0 0 1"/>
      <mass value="0.5"/>
      <inertia ixx="1.0" ixy="0.0" ixz="0.0" iyy="1.0" iyz="0.0" izz="1.0"/>
    </inertial>
  </link>
  <gazebo reference="sensor_link">
    <material value="Gazebo/Blue"/>
  </gazebo>
  <joint name="sensor_joint" type="fixed">
    <parent link="base_center"/>
    <child link="sensor_link"/>
    <origin rpy="0 0 0" xyz="0.39 0 0.215"/>
  </joint>
  <gazebo reference="base_center">
    <sensor name="laser" type="ray">
      <pose>0.39 0 0.215 0 0 0</pose>
      <visualize>true</visualize>
      <update_rate>40</update_rate>
      <ray>
        <scan>
          <horizontal>
            <samples>720</samples>
            <resolution>1</resolution>
            <min_angle>-1.57</min_angle>
            <max_angle>1.57</max_angle>
          </horizontal>
        </scan>
        <range>
          <min>0.1</min>
          <max>30.0</max>
          <resolution>0.01</resolution>
        </range>
        <noise>
          <type>gaussian</type>
          <mean>0.0</mean>
          <stddev>0.01</stddev>
        </noise>
      </ray>
      <plugin filename="libgazebo_ros_laser.so" name="gazebo_ros_head_hokuyo_controller">
        <topicName>/laser/scan</topicName>
        <frameName>base_center</frameName>
      </plugin>
    </sensor>
  </gazebo>
  <gazebo reference="sensor_link">
    <sensor name="camera" type="depth">
      <always_on>1</always_on>
      <update_rate>20.0</update_rate>
      <visualize>true</visualize>
      <camera>
        <horizontal_fov>1.047</horizontal_fov>
        <image>
          <width>640</width>
          <height>480</height>
          <format>R8G8B8</format>
        </image>
        <depth_camera>

            </depth_camera>
        <clip>
          <near>0.1</near>
          <far>20</far>
        </clip>
      </camera>
      <plugin filename="libgazebo_ros_openni_kinect.so" name="camera_plugin">
        <alwaysOn>true</alwaysOn>
        <updateRate>10.0</updateRate>
        <cameraName>camera</cameraName>
        <frameName>camera_link_optical</frameName>
        <imageTopicName>rgb/image_raw</imageTopicName>
        <depthImageTopicName>depth/image_raw</depthImageTopicName>
        <pointCloudTopicName>depth/points</pointCloudTopicName>
        <cameraInfoTopicName>rgb/camera_info</cameraInfoTopicName>
        <depthImageCameraInfoTopicName>depth/camera_info</depthImageCameraInfoTopicName>
        <pointCloudCutoff>0.4</pointCloudCutoff>
        <hackBaseline>0.07</hackBaseline>
        <distortionK1>0.0</distortionK1>
        <distortionK2>0.0</distortionK2>
        <distortionK3>0.0</distortionK3>
        <distortionT1>0.0</distortionT1>
        <distortionT2>0.0</distortionT2>
        <CxPrime>0.0</CxPrime>
        <Cx>0.0</Cx>
        <Cy>0.0</Cy>
        <focalLength>0.0</focalLength>
      </plugin>
    </sensor>
  </gazebo>
  <!--IMU-->
  <gazebo>
    <plugin filename="libgazebo_ros_imu.so" name="imu_plugin">
      <alwaysOn>true</alwaysOn>
      <bodyName>base_center</bodyName>
      <topicName>imu</topicName>
      <serviceName>imu_service</serviceName>
      <gaussianNoise>0.0</gaussianNoise>
      <updateRate>150.0</updateRate>
    </plugin>
  </gazebo>
  <gazebo>
    <plugin filename="libgazebo_ros_control.so" name="gazebo_ros_control">
</plugin>
  </gazebo>
</robot>

